Traceback (most recent call last):
  File "main.py", line 266, in <module>
    main(**vars(FLAGS))
  File "main.py", line 239, in main
    model.train_model(train_loader, valid_loader, kwargs["epochs"], kwargs["learning_rate"], kwargs["log"], kwargs["save"])
  File "/Users/emmagraham/Documents/GitHub/propagation/CLtargetprop/Models/bp.py", line 74, in train_model
    initial_valid_loss, initial_valid_acc = self.external_test(valid_loader)
  File "/Users/emmagraham/anaconda3/envs/target-prop/lib/python3.8/site-packages/torch/nn/modules/module.py", line 1688, in __getattr__
    raise AttributeError(f"'{type(self).__name__}' object has no attribute '{name}'")
AttributeError: 'bp_net' object has no attribute 'external_test'